2022-06-02 13:55:24,590 INFO    MainThread:296 [wandb_setup.py:_flush():76] Loading settings from /home/idhumal/.config/wandb/settings
2022-06-02 13:55:24,590 INFO    MainThread:296 [wandb_setup.py:_flush():76] Loading settings from /mnt/d/ImageNet-Downsampled/wandb/settings
2022-06-02 13:55:24,590 INFO    MainThread:296 [wandb_setup.py:_flush():76] Loading settings from environment variables: {}
2022-06-02 13:55:24,590 INFO    MainThread:296 [wandb_setup.py:_flush():76] Inferring run settings from compute environment: {'program_relpath': 'train.py', 'program': 'train.py'}
2022-06-02 13:55:24,590 INFO    MainThread:296 [wandb_init.py:_log_setup():428] Logging user logs to /mnt/d/ImageNet-Downsampled/wandb/run-20220602_135524-1gffwt1u/logs/debug.log
2022-06-02 13:55:24,591 INFO    MainThread:296 [wandb_init.py:_log_setup():429] Logging internal logs to /mnt/d/ImageNet-Downsampled/wandb/run-20220602_135524-1gffwt1u/logs/debug-internal.log
2022-06-02 13:55:24,591 INFO    MainThread:296 [wandb_init.py:init():462] calling init triggers
2022-06-02 13:55:24,591 INFO    MainThread:296 [wandb_init.py:init():465] wandb.init called with sweep_config: {}
config: {}
2022-06-02 13:55:24,592 INFO    MainThread:296 [wandb_init.py:init():515] starting backend
2022-06-02 13:55:24,592 INFO    MainThread:296 [backend.py:_multiprocessing_setup():97] multiprocessing start_methods=fork,spawn,forkserver, using: spawn
2022-06-02 13:55:24,603 INFO    MainThread:296 [backend.py:ensure_launched():217] starting backend process...
2022-06-02 13:55:24,611 INFO    MainThread:296 [backend.py:ensure_launched():222] started backend process with pid: 337
2022-06-02 13:55:24,612 INFO    MainThread:296 [wandb_init.py:init():525] backend started and connected
2022-06-02 13:55:24,619 INFO    MainThread:296 [wandb_init.py:init():596] updated telemetry
2022-06-02 13:55:24,676 INFO    MainThread:296 [wandb_init.py:init():627] communicating run to backend with 30 second timeout
2022-06-02 13:55:28,896 ERROR   Thread-1  :296 [retry.py:__call__():126] Retry attempt failed:
Traceback (most recent call last):
  File "/usr/lib/python3/dist-packages/urllib3/connection.py", line 159, in _new_conn
    conn = connection.create_connection(
  File "/usr/lib/python3/dist-packages/urllib3/util/connection.py", line 84, in create_connection
    raise err
  File "/usr/lib/python3/dist-packages/urllib3/util/connection.py", line 74, in create_connection
    sock.connect(sa)
OSError: [Errno 113] No route to host

During handling of the above exception, another exception occurred:

Traceback (most recent call last):
  File "/usr/lib/python3/dist-packages/urllib3/connectionpool.py", line 665, in urlopen
    httplib_response = self._make_request(
  File "/usr/lib/python3/dist-packages/urllib3/connectionpool.py", line 376, in _make_request
    self._validate_conn(conn)
  File "/usr/lib/python3/dist-packages/urllib3/connectionpool.py", line 996, in _validate_conn
    conn.connect()
  File "/usr/lib/python3/dist-packages/urllib3/connection.py", line 314, in connect
    conn = self._new_conn()
  File "/usr/lib/python3/dist-packages/urllib3/connection.py", line 171, in _new_conn
    raise NewConnectionError(
urllib3.exceptions.NewConnectionError: <urllib3.connection.VerifiedHTTPSConnection object at 0x7f2bb29848e0>: Failed to establish a new connection: [Errno 113] No route to host

During handling of the above exception, another exception occurred:

Traceback (most recent call last):
  File "/usr/lib/python3/dist-packages/requests/adapters.py", line 439, in send
    resp = conn.urlopen(
  File "/usr/lib/python3/dist-packages/urllib3/connectionpool.py", line 719, in urlopen
    retries = retries.increment(
  File "/usr/lib/python3/dist-packages/urllib3/util/retry.py", line 436, in increment
    raise MaxRetryError(_pool, url, error or ResponseError(cause))
urllib3.exceptions.MaxRetryError: HTTPSConnectionPool(host='api.wandb.ai', port=443): Max retries exceeded with url: /graphql (Caused by NewConnectionError('<urllib3.connection.VerifiedHTTPSConnection object at 0x7f2bb29848e0>: Failed to establish a new connection: [Errno 113] No route to host'))

During handling of the above exception, another exception occurred:

Traceback (most recent call last):
  File "/home/idhumal/.local/lib/python3.8/site-packages/wandb/sdk/lib/retry.py", line 102, in __call__
    result = self._call_fn(*args, **kwargs)
  File "/home/idhumal/.local/lib/python3.8/site-packages/wandb/sdk/internal/internal_api.py", line 140, in execute
    return self.client.execute(*args, **kwargs)
  File "/home/idhumal/.local/lib/python3.8/site-packages/wandb/vendor/gql-0.2.0/wandb_gql/client.py", line 52, in execute
    result = self._get_result(document, *args, **kwargs)
  File "/home/idhumal/.local/lib/python3.8/site-packages/wandb/vendor/gql-0.2.0/wandb_gql/client.py", line 60, in _get_result
    return self.transport.execute(document, *args, **kwargs)
  File "/home/idhumal/.local/lib/python3.8/site-packages/wandb/vendor/gql-0.2.0/wandb_gql/transport/requests.py", line 38, in execute
    request = requests.post(self.url, **post_args)
  File "/usr/lib/python3/dist-packages/requests/api.py", line 116, in post
    return request('post', url, data=data, json=json, **kwargs)
  File "/usr/lib/python3/dist-packages/requests/api.py", line 60, in request
    return session.request(method=method, url=url, **kwargs)
  File "/usr/lib/python3/dist-packages/requests/sessions.py", line 533, in request
    resp = self.send(prep, **send_kwargs)
  File "/usr/lib/python3/dist-packages/requests/sessions.py", line 646, in send
    r = adapter.send(request, **kwargs)
  File "/usr/lib/python3/dist-packages/requests/adapters.py", line 516, in send
    raise ConnectionError(e, request=request)
requests.exceptions.ConnectionError: HTTPSConnectionPool(host='api.wandb.ai', port=443): Max retries exceeded with url: /graphql (Caused by NewConnectionError('<urllib3.connection.VerifiedHTTPSConnection object at 0x7f2bb29848e0>: Failed to establish a new connection: [Errno 113] No route to host'))
2022-06-02 13:55:54,677 INFO    MainThread:296 [interface_shared.py:_communicate_run():326] couldn't get run from backend
2022-06-02 13:55:54,677 ERROR   MainThread:296 [wandb_init.py:init():636] backend process timed out
2022-06-02 13:55:54,677 ERROR   MainThread:296 [wandb_init.py:init():647] encountered error: Error communicating with wandb process
try: wandb.init(settings=wandb.Settings(start_method='fork'))
or:  wandb.init(settings=wandb.Settings(start_method='thread'))
For more info see: https://docs.wandb.ai/library/init#init-start-error
2022-06-02 13:58:23,170 WARNING MainThread:296 [wandb_init.py:init():1020] interrupted
Traceback (most recent call last):
  File "/home/idhumal/.local/lib/python3.8/site-packages/wandb/sdk/wandb_init.py", line 999, in init
    run = wi.init()
  File "/home/idhumal/.local/lib/python3.8/site-packages/wandb/sdk/wandb_init.py", line 651, in init
    backend.cleanup()
  File "/home/idhumal/.local/lib/python3.8/site-packages/wandb/sdk/backend/backend.py", line 248, in cleanup
    self.wandb_process.join()
  File "/usr/lib/python3.8/multiprocessing/process.py", line 149, in join
    res = self._popen.wait(timeout)
  File "/usr/lib/python3.8/multiprocessing/popen_fork.py", line 47, in wait
    return self.poll(os.WNOHANG if timeout == 0.0 else 0)
  File "/usr/lib/python3.8/multiprocessing/popen_fork.py", line 27, in poll
    pid, sts = os.waitpid(self.pid, flag)
KeyboardInterrupt
